Traceback (most recent call last):
  File "/home/sano_anju/errlocator/sample/raise/raise3.py", line 9, in <module>
    raise ValueError("aaa")
ValueError: aaa