Traceback (most recent call last):
  File "/home/sano_anju/01/sample/raise/raise1.py", line 4, in <module>
    raise Exception
Exception