Traceback (most recent call last):
  File "/home/sano_anju/01/sample/ValueError/v04.py", line 9, in <module>
    print(sum(x))
          ^^^^^^
  File "/home/sano_anju/01/sample/ValueError/v04.py", line 4, in sum
    for i in range(1, n + 1, x):
             ^^^^^^^^^^^^^^^^^^
ValueError: range() arg 3 must not be zero